INFO 2025-08-21 07:56:58,071 autoreload 35148 36472 Watching for file changes with StatReloader
INFO 2025-08-21 08:10:16,986 autoreload 33628 27928 Watching for file changes with StatReloader
INFO 2025-08-21 08:13:33,552 autoreload 25176 31852 Watching for file changes with StatReloader
INFO 2025-08-21 08:14:10,026 autoreload 25176 31852 D:\LECTURES\MY CODES\javascript\Budgetly\Backend\categories\views.py changed, reloading.
INFO 2025-08-21 08:14:12,020 autoreload 36248 30744 Watching for file changes with StatReloader
INFO 2025-08-21 08:14:52,977 autoreload 2148 34760 Watching for file changes with StatReloader
INFO 2025-08-21 08:15:05,930 autoreload 2148 34760 D:\LECTURES\MY CODES\javascript\Budgetly\Backend\categories\views.py changed, reloading.
INFO 2025-08-21 08:15:08,006 autoreload 2068 14724 Watching for file changes with StatReloader
INFO 2025-08-21 08:15:33,776 autoreload 2068 14724 D:\LECTURES\MY CODES\javascript\Budgetly\Backend\budgets\models.py changed, reloading.
INFO 2025-08-21 08:15:35,730 autoreload 28916 23392 Watching for file changes with StatReloader
INFO 2025-08-21 08:15:58,965 autoreload 28916 23392 D:\LECTURES\MY CODES\javascript\Budgetly\Backend\templates\models.py changed, reloading.
INFO 2025-08-21 08:16:00,985 autoreload 7556 25636 Watching for file changes with StatReloader
WARNING 2025-08-21 08:17:03,895 log 7556 38328 Not Found: /api/
WARNING 2025-08-21 08:17:03,897 basehttp 7556 38328 "GET /api/ HTTP/1.1" 404 3437
WARNING 2025-08-21 08:17:20,100 log 7556 27600 Method Not Allowed: /api/token/
WARNING 2025-08-21 08:17:20,103 basehttp 7556 27600 "GET /api/token/ HTTP/1.1" 405 40
INFO 2025-08-21 08:19:56,466 basehttp 7556 1408 "OPTIONS /api/accounts/register/ HTTP/1.1" 200 0
ERROR 2025-08-21 08:19:56,945 log 7556 1408 Internal Server Error: /api/accounts/register/
Traceback (most recent call last):
  File "C:\Users\JOSH\AppData\Roaming\Python\Python313\site-packages\django\db\backends\utils.py", line 105, in _execute
    return self.cursor.execute(sql, params)
           ~~~~~~~~~~~~~~~~~~~^^^^^^^^^^^^^
  File "C:\Users\JOSH\AppData\Roaming\Python\Python313\site-packages\django\db\backends\sqlite3\base.py", line 329, in execute
    return super().execute(query, params)
           ~~~~~~~~~~~~~~~^^^^^^^^^^^^^^^
sqlite3.OperationalError: no such table: accounts_user

The above exception was the direct cause of the following exception:

Traceback (most recent call last):
  File "C:\Users\JOSH\AppData\Roaming\Python\Python313\site-packages\django\core\handlers\exception.py", line 55, in inner
    response = get_response(request)
  File "C:\Users\JOSH\AppData\Roaming\Python\Python313\site-packages\django\core\handlers\base.py", line 197, in _get_response
    response = wrapped_callback(request, *callback_args, **callback_kwargs)
  File "C:\Users\JOSH\AppData\Roaming\Python\Python313\site-packages\django\views\decorators\csrf.py", line 65, in _view_wrapper
    return view_func(request, *args, **kwargs)
  File "C:\Users\JOSH\AppData\Roaming\Python\Python313\site-packages\django\views\generic\base.py", line 104, in view
    return self.dispatch(request, *args, **kwargs)
           ~~~~~~~~~~~~~^^^^^^^^^^^^^^^^^^^^^^^^^^
  File "C:\Users\JOSH\AppData\Roaming\Python\Python313\site-packages\rest_framework\views.py", line 509, in dispatch
    response = self.handle_exception(exc)
  File "C:\Users\JOSH\AppData\Roaming\Python\Python313\site-packages\rest_framework\views.py", line 469, in handle_exception
    self.raise_uncaught_exception(exc)
    ~~~~~~~~~~~~~~~~~~~~~~~~~~~~~^^^^^
  File "C:\Users\JOSH\AppData\Roaming\Python\Python313\site-packages\rest_framework\views.py", line 480, in raise_uncaught_exception
    raise exc
  File "C:\Users\JOSH\AppData\Roaming\Python\Python313\site-packages\rest_framework\views.py", line 506, in dispatch
    response = handler(request, *args, **kwargs)
  File "D:\LECTURES\MY CODES\javascript\Budgetly\backend\accounts\views.py", line 28, in post
    if serializer.is_valid():
       ~~~~~~~~~~~~~~~~~~~^^
  File "C:\Users\JOSH\AppData\Roaming\Python\Python313\site-packages\rest_framework\serializers.py", line 223, in is_valid
    self._validated_data = self.run_validation(self.initial_data)
                           ~~~~~~~~~~~~~~~~~~~^^^^^^^^^^^^^^^^^^^
  File "C:\Users\JOSH\AppData\Roaming\Python\Python313\site-packages\rest_framework\serializers.py", line 442, in run_validation
    value = self.to_internal_value(data)
  File "C:\Users\JOSH\AppData\Roaming\Python\Python313\site-packages\rest_framework\serializers.py", line 499, in to_internal_value
    validated_value = field.run_validation(primitive_value)
  File "C:\Users\JOSH\AppData\Roaming\Python\Python313\site-packages\rest_framework\fields.py", line 759, in run_validation
    return super().run_validation(data)
           ~~~~~~~~~~~~~~~~~~~~~~^^^^^^
  File "C:\Users\JOSH\AppData\Roaming\Python\Python313\site-packages\rest_framework\fields.py", line 541, in run_validation
    self.run_validators(value)
    ~~~~~~~~~~~~~~~~~~~^^^^^^^
  File "C:\Users\JOSH\AppData\Roaming\Python\Python313\site-packages\rest_framework\fields.py", line 553, in run_validators
    validator(value, self)
    ~~~~~~~~~^^^^^^^^^^^^^
  File "C:\Users\JOSH\AppData\Roaming\Python\Python313\site-packages\rest_framework\validators.py", line 73, in __call__
    if qs_exists(queryset):
       ~~~~~~~~~^^^^^^^^^^
  File "C:\Users\JOSH\AppData\Roaming\Python\Python313\site-packages\rest_framework\validators.py", line 21, in qs_exists
    return queryset.exists()
           ~~~~~~~~~~~~~~~^^
  File "C:\Users\JOSH\AppData\Roaming\Python\Python313\site-packages\django\db\models\query.py", line 1288, in exists
    return self.query.has_results(using=self.db)
           ~~~~~~~~~~~~~~~~~~~~~~^^^^^^^^^^^^^^^
  File "C:\Users\JOSH\AppData\Roaming\Python\Python313\site-packages\django\db\models\sql\query.py", line 659, in has_results
    return compiler.has_results()
           ~~~~~~~~~~~~~~~~~~~~^^
  File "C:\Users\JOSH\AppData\Roaming\Python\Python313\site-packages\django\db\models\sql\compiler.py", line 1530, in has_results
    return bool(self.execute_sql(SINGLE))
                ~~~~~~~~~~~~~~~~^^^^^^^^
  File "C:\Users\JOSH\AppData\Roaming\Python\Python313\site-packages\django\db\models\sql\compiler.py", line 1562, in execute_sql
    cursor.execute(sql, params)
    ~~~~~~~~~~~~~~^^^^^^^^^^^^^
  File "C:\Users\JOSH\AppData\Roaming\Python\Python313\site-packages\django\db\backends\utils.py", line 122, in execute
    return super().execute(sql, params)
           ~~~~~~~~~~~~~~~^^^^^^^^^^^^^
  File "C:\Users\JOSH\AppData\Roaming\Python\Python313\site-packages\django\db\backends\utils.py", line 79, in execute
    return self._execute_with_wrappers(
           ~~~~~~~~~~~~~~~~~~~~~~~~~~~^
        sql, params, many=False, executor=self._execute
        ^^^^^^^^^^^^^^^^^^^^^^^^^^^^^^^^^^^^^^^^^^^^^^^
    )
    ^
  File "C:\Users\JOSH\AppData\Roaming\Python\Python313\site-packages\django\db\backends\utils.py", line 92, in _execute_with_wrappers
    return executor(sql, params, many, context)
  File "C:\Users\JOSH\AppData\Roaming\Python\Python313\site-packages\django\db\backends\utils.py", line 100, in _execute
    with self.db.wrap_database_errors:
         ^^^^^^^^^^^^^^^^^^^^^^^^^^^^
  File "C:\Users\JOSH\AppData\Roaming\Python\Python313\site-packages\django\db\utils.py", line 91, in __exit__
    raise dj_exc_value.with_traceback(traceback) from exc_value
  File "C:\Users\JOSH\AppData\Roaming\Python\Python313\site-packages\django\db\backends\utils.py", line 105, in _execute
    return self.cursor.execute(sql, params)
           ~~~~~~~~~~~~~~~~~~~^^^^^^^^^^^^^
  File "C:\Users\JOSH\AppData\Roaming\Python\Python313\site-packages\django\db\backends\sqlite3\base.py", line 329, in execute
    return super().execute(query, params)
           ~~~~~~~~~~~~~~~^^^^^^^^^^^^^^^
django.db.utils.OperationalError: no such table: accounts_user
ERROR 2025-08-21 08:19:57,006 basehttp 7556 1408 "POST /api/accounts/register/ HTTP/1.1" 500 213192
INFO 2025-08-21 08:23:03,956 basehttp 7556 28608 "OPTIONS /api/token/ HTTP/1.1" 200 0
ERROR 2025-08-21 08:23:04,240 log 7556 28608 Internal Server Error: /api/token/
Traceback (most recent call last):
  File "C:\Users\JOSH\AppData\Roaming\Python\Python313\site-packages\django\db\backends\utils.py", line 105, in _execute
    return self.cursor.execute(sql, params)
           ~~~~~~~~~~~~~~~~~~~^^^^^^^^^^^^^
  File "C:\Users\JOSH\AppData\Roaming\Python\Python313\site-packages\django\db\backends\sqlite3\base.py", line 329, in execute
    return super().execute(query, params)
           ~~~~~~~~~~~~~~~^^^^^^^^^^^^^^^
sqlite3.OperationalError: no such table: accounts_user

The above exception was the direct cause of the following exception:

Traceback (most recent call last):
  File "C:\Users\JOSH\AppData\Roaming\Python\Python313\site-packages\django\core\handlers\exception.py", line 55, in inner
    response = get_response(request)
  File "C:\Users\JOSH\AppData\Roaming\Python\Python313\site-packages\django\core\handlers\base.py", line 197, in _get_response
    response = wrapped_callback(request, *callback_args, **callback_kwargs)
  File "C:\Users\JOSH\AppData\Roaming\Python\Python313\site-packages\django\views\decorators\csrf.py", line 65, in _view_wrapper
    return view_func(request, *args, **kwargs)
  File "C:\Users\JOSH\AppData\Roaming\Python\Python313\site-packages\django\views\generic\base.py", line 104, in view
    return self.dispatch(request, *args, **kwargs)
           ~~~~~~~~~~~~~^^^^^^^^^^^^^^^^^^^^^^^^^^
  File "C:\Users\JOSH\AppData\Roaming\Python\Python313\site-packages\rest_framework\views.py", line 509, in dispatch
    response = self.handle_exception(exc)
  File "C:\Users\JOSH\AppData\Roaming\Python\Python313\site-packages\rest_framework\views.py", line 469, in handle_exception
    self.raise_uncaught_exception(exc)
    ~~~~~~~~~~~~~~~~~~~~~~~~~~~~~^^^^^
  File "C:\Users\JOSH\AppData\Roaming\Python\Python313\site-packages\rest_framework\views.py", line 480, in raise_uncaught_exception
    raise exc
  File "C:\Users\JOSH\AppData\Roaming\Python\Python313\site-packages\rest_framework\views.py", line 506, in dispatch
    response = handler(request, *args, **kwargs)
  File "C:\Users\JOSH\AppData\Roaming\Python\Python313\site-packages\rest_framework_simplejwt\views.py", line 44, in post
    serializer.is_valid(raise_exception=True)
    ~~~~~~~~~~~~~~~~~~~^^^^^^^^^^^^^^^^^^^^^^
  File "C:\Users\JOSH\AppData\Roaming\Python\Python313\site-packages\rest_framework\serializers.py", line 223, in is_valid
    self._validated_data = self.run_validation(self.initial_data)
                           ~~~~~~~~~~~~~~~~~~~^^^^^^^^^^^^^^^^^^^
  File "C:\Users\JOSH\AppData\Roaming\Python\Python313\site-packages\rest_framework\serializers.py", line 445, in run_validation
    value = self.validate(value)
  File "C:\Users\JOSH\AppData\Roaming\Python\Python313\site-packages\rest_framework_simplejwt\serializers.py", line 73, in validate
    data = super().validate(attrs)
  File "C:\Users\JOSH\AppData\Roaming\Python\Python313\site-packages\rest_framework_simplejwt\serializers.py", line 54, in validate
    self.user = authenticate(**authenticate_kwargs)
                ~~~~~~~~~~~~^^^^^^^^^^^^^^^^^^^^^^^
  File "C:\Users\JOSH\AppData\Roaming\Python\Python313\site-packages\django\views\decorators\debug.py", line 73, in sensitive_variables_wrapper
    return func(*func_args, **func_kwargs)
  File "C:\Users\JOSH\AppData\Roaming\Python\Python313\site-packages\django\contrib\auth\__init__.py", line 79, in authenticate
    user = backend.authenticate(request, **credentials)
  File "C:\Users\JOSH\AppData\Roaming\Python\Python313\site-packages\django\contrib\auth\backends.py", line 42, in authenticate
    user = UserModel._default_manager.get_by_natural_key(username)
  File "C:\Users\JOSH\AppData\Roaming\Python\Python313\site-packages\django\contrib\auth\base_user.py", line 56, in get_by_natural_key
    return self.get(**{self.model.USERNAME_FIELD: username})
           ~~~~~~~~^^^^^^^^^^^^^^^^^^^^^^^^^^^^^^^^^^^^^^^^^
  File "C:\Users\JOSH\AppData\Roaming\Python\Python313\site-packages\django\db\models\manager.py", line 87, in manager_method
    return getattr(self.get_queryset(), name)(*args, **kwargs)
           ~~~~~~~~~~~~~~~~~~~~~~~~~~~~~~~~~~^^^^^^^^^^^^^^^^^
  File "C:\Users\JOSH\AppData\Roaming\Python\Python313\site-packages\django\db\models\query.py", line 645, in get
    num = len(clone)
  File "C:\Users\JOSH\AppData\Roaming\Python\Python313\site-packages\django\db\models\query.py", line 382, in __len__
    self._fetch_all()
    ~~~~~~~~~~~~~~~^^
  File "C:\Users\JOSH\AppData\Roaming\Python\Python313\site-packages\django\db\models\query.py", line 1928, in _fetch_all
    self._result_cache = list(self._iterable_class(self))
                         ~~~~^^^^^^^^^^^^^^^^^^^^^^^^^^^^
  File "C:\Users\JOSH\AppData\Roaming\Python\Python313\site-packages\django\db\models\query.py", line 91, in __iter__
    results = compiler.execute_sql(
        chunked_fetch=self.chunked_fetch, chunk_size=self.chunk_size
    )
  File "C:\Users\JOSH\AppData\Roaming\Python\Python313\site-packages\django\db\models\sql\compiler.py", line 1562, in execute_sql
    cursor.execute(sql, params)
    ~~~~~~~~~~~~~~^^^^^^^^^^^^^
  File "C:\Users\JOSH\AppData\Roaming\Python\Python313\site-packages\django\db\backends\utils.py", line 122, in execute
    return super().execute(sql, params)
           ~~~~~~~~~~~~~~~^^^^^^^^^^^^^
  File "C:\Users\JOSH\AppData\Roaming\Python\Python313\site-packages\django\db\backends\utils.py", line 79, in execute
    return self._execute_with_wrappers(
           ~~~~~~~~~~~~~~~~~~~~~~~~~~~^
        sql, params, many=False, executor=self._execute
        ^^^^^^^^^^^^^^^^^^^^^^^^^^^^^^^^^^^^^^^^^^^^^^^
    )
    ^
  File "C:\Users\JOSH\AppData\Roaming\Python\Python313\site-packages\django\db\backends\utils.py", line 92, in _execute_with_wrappers
    return executor(sql, params, many, context)
  File "C:\Users\JOSH\AppData\Roaming\Python\Python313\site-packages\django\db\backends\utils.py", line 100, in _execute
    with self.db.wrap_database_errors:
         ^^^^^^^^^^^^^^^^^^^^^^^^^^^^
  File "C:\Users\JOSH\AppData\Roaming\Python\Python313\site-packages\django\db\utils.py", line 91, in __exit__
    raise dj_exc_value.with_traceback(traceback) from exc_value
  File "C:\Users\JOSH\AppData\Roaming\Python\Python313\site-packages\django\db\backends\utils.py", line 105, in _execute
    return self.cursor.execute(sql, params)
           ~~~~~~~~~~~~~~~~~~~^^^^^^^^^^^^^
  File "C:\Users\JOSH\AppData\Roaming\Python\Python313\site-packages\django\db\backends\sqlite3\base.py", line 329, in execute
    return super().execute(query, params)
           ~~~~~~~~~~~~~~~^^^^^^^^^^^^^^^
django.db.utils.OperationalError: no such table: accounts_user
ERROR 2025-08-21 08:23:04,296 basehttp 7556 28608 "POST /api/token/ HTTP/1.1" 500 223615
ERROR 2025-08-21 08:23:55,757 log 7556 28608 Internal Server Error: /api/token/
Traceback (most recent call last):
  File "C:\Users\JOSH\AppData\Roaming\Python\Python313\site-packages\django\db\backends\utils.py", line 105, in _execute
    return self.cursor.execute(sql, params)
           ~~~~~~~~~~~~~~~~~~~^^^^^^^^^^^^^
  File "C:\Users\JOSH\AppData\Roaming\Python\Python313\site-packages\django\db\backends\sqlite3\base.py", line 329, in execute
    return super().execute(query, params)
           ~~~~~~~~~~~~~~~^^^^^^^^^^^^^^^
sqlite3.OperationalError: no such table: accounts_user

The above exception was the direct cause of the following exception:

Traceback (most recent call last):
  File "C:\Users\JOSH\AppData\Roaming\Python\Python313\site-packages\django\core\handlers\exception.py", line 55, in inner
    response = get_response(request)
  File "C:\Users\JOSH\AppData\Roaming\Python\Python313\site-packages\django\core\handlers\base.py", line 197, in _get_response
    response = wrapped_callback(request, *callback_args, **callback_kwargs)
  File "C:\Users\JOSH\AppData\Roaming\Python\Python313\site-packages\django\views\decorators\csrf.py", line 65, in _view_wrapper
    return view_func(request, *args, **kwargs)
  File "C:\Users\JOSH\AppData\Roaming\Python\Python313\site-packages\django\views\generic\base.py", line 104, in view
    return self.dispatch(request, *args, **kwargs)
           ~~~~~~~~~~~~~^^^^^^^^^^^^^^^^^^^^^^^^^^
  File "C:\Users\JOSH\AppData\Roaming\Python\Python313\site-packages\rest_framework\views.py", line 509, in dispatch
    response = self.handle_exception(exc)
  File "C:\Users\JOSH\AppData\Roaming\Python\Python313\site-packages\rest_framework\views.py", line 469, in handle_exception
    self.raise_uncaught_exception(exc)
    ~~~~~~~~~~~~~~~~~~~~~~~~~~~~~^^^^^
  File "C:\Users\JOSH\AppData\Roaming\Python\Python313\site-packages\rest_framework\views.py", line 480, in raise_uncaught_exception
    raise exc
  File "C:\Users\JOSH\AppData\Roaming\Python\Python313\site-packages\rest_framework\views.py", line 506, in dispatch
    response = handler(request, *args, **kwargs)
  File "C:\Users\JOSH\AppData\Roaming\Python\Python313\site-packages\rest_framework_simplejwt\views.py", line 44, in post
    serializer.is_valid(raise_exception=True)
    ~~~~~~~~~~~~~~~~~~~^^^^^^^^^^^^^^^^^^^^^^
  File "C:\Users\JOSH\AppData\Roaming\Python\Python313\site-packages\rest_framework\serializers.py", line 223, in is_valid
    self._validated_data = self.run_validation(self.initial_data)
                           ~~~~~~~~~~~~~~~~~~~^^^^^^^^^^^^^^^^^^^
  File "C:\Users\JOSH\AppData\Roaming\Python\Python313\site-packages\rest_framework\serializers.py", line 445, in run_validation
    value = self.validate(value)
  File "C:\Users\JOSH\AppData\Roaming\Python\Python313\site-packages\rest_framework_simplejwt\serializers.py", line 73, in validate
    data = super().validate(attrs)
  File "C:\Users\JOSH\AppData\Roaming\Python\Python313\site-packages\rest_framework_simplejwt\serializers.py", line 54, in validate
    self.user = authenticate(**authenticate_kwargs)
                ~~~~~~~~~~~~^^^^^^^^^^^^^^^^^^^^^^^
  File "C:\Users\JOSH\AppData\Roaming\Python\Python313\site-packages\django\views\decorators\debug.py", line 73, in sensitive_variables_wrapper
    return func(*func_args, **func_kwargs)
  File "C:\Users\JOSH\AppData\Roaming\Python\Python313\site-packages\django\contrib\auth\__init__.py", line 79, in authenticate
    user = backend.authenticate(request, **credentials)
  File "C:\Users\JOSH\AppData\Roaming\Python\Python313\site-packages\django\contrib\auth\backends.py", line 42, in authenticate
    user = UserModel._default_manager.get_by_natural_key(username)
  File "C:\Users\JOSH\AppData\Roaming\Python\Python313\site-packages\django\contrib\auth\base_user.py", line 56, in get_by_natural_key
    return self.get(**{self.model.USERNAME_FIELD: username})
           ~~~~~~~~^^^^^^^^^^^^^^^^^^^^^^^^^^^^^^^^^^^^^^^^^
  File "C:\Users\JOSH\AppData\Roaming\Python\Python313\site-packages\django\db\models\manager.py", line 87, in manager_method
    return getattr(self.get_queryset(), name)(*args, **kwargs)
           ~~~~~~~~~~~~~~~~~~~~~~~~~~~~~~~~~~^^^^^^^^^^^^^^^^^
  File "C:\Users\JOSH\AppData\Roaming\Python\Python313\site-packages\django\db\models\query.py", line 645, in get
    num = len(clone)
  File "C:\Users\JOSH\AppData\Roaming\Python\Python313\site-packages\django\db\models\query.py", line 382, in __len__
    self._fetch_all()
    ~~~~~~~~~~~~~~~^^
  File "C:\Users\JOSH\AppData\Roaming\Python\Python313\site-packages\django\db\models\query.py", line 1928, in _fetch_all
    self._result_cache = list(self._iterable_class(self))
                         ~~~~^^^^^^^^^^^^^^^^^^^^^^^^^^^^
  File "C:\Users\JOSH\AppData\Roaming\Python\Python313\site-packages\django\db\models\query.py", line 91, in __iter__
    results = compiler.execute_sql(
        chunked_fetch=self.chunked_fetch, chunk_size=self.chunk_size
    )
  File "C:\Users\JOSH\AppData\Roaming\Python\Python313\site-packages\django\db\models\sql\compiler.py", line 1562, in execute_sql
    cursor.execute(sql, params)
    ~~~~~~~~~~~~~~^^^^^^^^^^^^^
  File "C:\Users\JOSH\AppData\Roaming\Python\Python313\site-packages\django\db\backends\utils.py", line 122, in execute
    return super().execute(sql, params)
           ~~~~~~~~~~~~~~~^^^^^^^^^^^^^
  File "C:\Users\JOSH\AppData\Roaming\Python\Python313\site-packages\django\db\backends\utils.py", line 79, in execute
    return self._execute_with_wrappers(
           ~~~~~~~~~~~~~~~~~~~~~~~~~~~^
        sql, params, many=False, executor=self._execute
        ^^^^^^^^^^^^^^^^^^^^^^^^^^^^^^^^^^^^^^^^^^^^^^^
    )
    ^
  File "C:\Users\JOSH\AppData\Roaming\Python\Python313\site-packages\django\db\backends\utils.py", line 92, in _execute_with_wrappers
    return executor(sql, params, many, context)
  File "C:\Users\JOSH\AppData\Roaming\Python\Python313\site-packages\django\db\backends\utils.py", line 100, in _execute
    with self.db.wrap_database_errors:
         ^^^^^^^^^^^^^^^^^^^^^^^^^^^^
  File "C:\Users\JOSH\AppData\Roaming\Python\Python313\site-packages\django\db\utils.py", line 91, in __exit__
    raise dj_exc_value.with_traceback(traceback) from exc_value
  File "C:\Users\JOSH\AppData\Roaming\Python\Python313\site-packages\django\db\backends\utils.py", line 105, in _execute
    return self.cursor.execute(sql, params)
           ~~~~~~~~~~~~~~~~~~~^^^^^^^^^^^^^
  File "C:\Users\JOSH\AppData\Roaming\Python\Python313\site-packages\django\db\backends\sqlite3\base.py", line 329, in execute
    return super().execute(query, params)
           ~~~~~~~~~~~~~~~^^^^^^^^^^^^^^^
django.db.utils.OperationalError: no such table: accounts_user
ERROR 2025-08-21 08:23:55,774 basehttp 7556 28608 "POST /api/token/ HTTP/1.1" 500 223615
INFO 2025-08-21 08:28:10,114 autoreload 7556 25636 D:\LECTURES\MY CODES\javascript\Budgetly\Backend\chatbot\models.py changed, reloading.
INFO 2025-08-21 08:28:12,584 autoreload 27732 36596 Watching for file changes with StatReloader
ERROR 2025-08-21 08:29:22,060 log 27732 13848 Internal Server Error: /api/accounts/register/
Traceback (most recent call last):
  File "C:\Users\JOSH\AppData\Roaming\Python\Python313\site-packages\django\db\backends\utils.py", line 105, in _execute
    return self.cursor.execute(sql, params)
           ~~~~~~~~~~~~~~~~~~~^^^^^^^^^^^^^
  File "C:\Users\JOSH\AppData\Roaming\Python\Python313\site-packages\django\db\backends\sqlite3\base.py", line 329, in execute
    return super().execute(query, params)
           ~~~~~~~~~~~~~~~^^^^^^^^^^^^^^^
sqlite3.OperationalError: no such table: accounts_user

The above exception was the direct cause of the following exception:

Traceback (most recent call last):
  File "C:\Users\JOSH\AppData\Roaming\Python\Python313\site-packages\django\core\handlers\exception.py", line 55, in inner
    response = get_response(request)
  File "C:\Users\JOSH\AppData\Roaming\Python\Python313\site-packages\django\core\handlers\base.py", line 197, in _get_response
    response = wrapped_callback(request, *callback_args, **callback_kwargs)
  File "C:\Users\JOSH\AppData\Roaming\Python\Python313\site-packages\django\views\decorators\csrf.py", line 65, in _view_wrapper
    return view_func(request, *args, **kwargs)
  File "C:\Users\JOSH\AppData\Roaming\Python\Python313\site-packages\django\views\generic\base.py", line 104, in view
    return self.dispatch(request, *args, **kwargs)
           ~~~~~~~~~~~~~^^^^^^^^^^^^^^^^^^^^^^^^^^
  File "C:\Users\JOSH\AppData\Roaming\Python\Python313\site-packages\rest_framework\views.py", line 509, in dispatch
    response = self.handle_exception(exc)
  File "C:\Users\JOSH\AppData\Roaming\Python\Python313\site-packages\rest_framework\views.py", line 469, in handle_exception
    self.raise_uncaught_exception(exc)
    ~~~~~~~~~~~~~~~~~~~~~~~~~~~~~^^^^^
  File "C:\Users\JOSH\AppData\Roaming\Python\Python313\site-packages\rest_framework\views.py", line 480, in raise_uncaught_exception
    raise exc
  File "C:\Users\JOSH\AppData\Roaming\Python\Python313\site-packages\rest_framework\views.py", line 506, in dispatch
    response = handler(request, *args, **kwargs)
  File "D:\LECTURES\MY CODES\javascript\Budgetly\backend\accounts\views.py", line 28, in post
    if serializer.is_valid():
       ~~~~~~~~~~~~~~~~~~~^^
  File "C:\Users\JOSH\AppData\Roaming\Python\Python313\site-packages\rest_framework\serializers.py", line 223, in is_valid
    self._validated_data = self.run_validation(self.initial_data)
                           ~~~~~~~~~~~~~~~~~~~^^^^^^^^^^^^^^^^^^^
  File "C:\Users\JOSH\AppData\Roaming\Python\Python313\site-packages\rest_framework\serializers.py", line 442, in run_validation
    value = self.to_internal_value(data)
  File "C:\Users\JOSH\AppData\Roaming\Python\Python313\site-packages\rest_framework\serializers.py", line 499, in to_internal_value
    validated_value = field.run_validation(primitive_value)
  File "C:\Users\JOSH\AppData\Roaming\Python\Python313\site-packages\rest_framework\fields.py", line 759, in run_validation
    return super().run_validation(data)
           ~~~~~~~~~~~~~~~~~~~~~~^^^^^^
  File "C:\Users\JOSH\AppData\Roaming\Python\Python313\site-packages\rest_framework\fields.py", line 541, in run_validation
    self.run_validators(value)
    ~~~~~~~~~~~~~~~~~~~^^^^^^^
  File "C:\Users\JOSH\AppData\Roaming\Python\Python313\site-packages\rest_framework\fields.py", line 553, in run_validators
    validator(value, self)
    ~~~~~~~~~^^^^^^^^^^^^^
  File "C:\Users\JOSH\AppData\Roaming\Python\Python313\site-packages\rest_framework\validators.py", line 73, in __call__
    if qs_exists(queryset):
       ~~~~~~~~~^^^^^^^^^^
  File "C:\Users\JOSH\AppData\Roaming\Python\Python313\site-packages\rest_framework\validators.py", line 21, in qs_exists
    return queryset.exists()
           ~~~~~~~~~~~~~~~^^
  File "C:\Users\JOSH\AppData\Roaming\Python\Python313\site-packages\django\db\models\query.py", line 1288, in exists
    return self.query.has_results(using=self.db)
           ~~~~~~~~~~~~~~~~~~~~~~^^^^^^^^^^^^^^^
  File "C:\Users\JOSH\AppData\Roaming\Python\Python313\site-packages\django\db\models\sql\query.py", line 659, in has_results
    return compiler.has_results()
           ~~~~~~~~~~~~~~~~~~~~^^
  File "C:\Users\JOSH\AppData\Roaming\Python\Python313\site-packages\django\db\models\sql\compiler.py", line 1530, in has_results
    return bool(self.execute_sql(SINGLE))
                ~~~~~~~~~~~~~~~~^^^^^^^^
  File "C:\Users\JOSH\AppData\Roaming\Python\Python313\site-packages\django\db\models\sql\compiler.py", line 1562, in execute_sql
    cursor.execute(sql, params)
    ~~~~~~~~~~~~~~^^^^^^^^^^^^^
  File "C:\Users\JOSH\AppData\Roaming\Python\Python313\site-packages\django\db\backends\utils.py", line 122, in execute
    return super().execute(sql, params)
           ~~~~~~~~~~~~~~~^^^^^^^^^^^^^
  File "C:\Users\JOSH\AppData\Roaming\Python\Python313\site-packages\django\db\backends\utils.py", line 79, in execute
    return self._execute_with_wrappers(
           ~~~~~~~~~~~~~~~~~~~~~~~~~~~^
        sql, params, many=False, executor=self._execute
        ^^^^^^^^^^^^^^^^^^^^^^^^^^^^^^^^^^^^^^^^^^^^^^^
    )
    ^
  File "C:\Users\JOSH\AppData\Roaming\Python\Python313\site-packages\django\db\backends\utils.py", line 92, in _execute_with_wrappers
    return executor(sql, params, many, context)
  File "C:\Users\JOSH\AppData\Roaming\Python\Python313\site-packages\django\db\backends\utils.py", line 100, in _execute
    with self.db.wrap_database_errors:
         ^^^^^^^^^^^^^^^^^^^^^^^^^^^^
  File "C:\Users\JOSH\AppData\Roaming\Python\Python313\site-packages\django\db\utils.py", line 91, in __exit__
    raise dj_exc_value.with_traceback(traceback) from exc_value
  File "C:\Users\JOSH\AppData\Roaming\Python\Python313\site-packages\django\db\backends\utils.py", line 105, in _execute
    return self.cursor.execute(sql, params)
           ~~~~~~~~~~~~~~~~~~~^^^^^^^^^^^^^
  File "C:\Users\JOSH\AppData\Roaming\Python\Python313\site-packages\django\db\backends\sqlite3\base.py", line 329, in execute
    return super().execute(query, params)
           ~~~~~~~~~~~~~~~^^^^^^^^^^^^^^^
django.db.utils.OperationalError: no such table: accounts_user
ERROR 2025-08-21 08:29:22,118 basehttp 27732 13848 "POST /api/accounts/register/ HTTP/1.1" 500 212850
INFO 2025-08-21 08:34:07,485 autoreload 36788 3576 Watching for file changes with StatReloader
WARNING 2025-08-21 08:35:07,404 log 36788 32872 Bad Request: /api/accounts/register/
WARNING 2025-08-21 08:35:07,407 basehttp 36788 32872 "POST /api/accounts/register/ HTTP/1.1" 400 159
WARNING 2025-08-21 08:42:47,496 log 36788 27160 Bad Request: /api/accounts/register/
WARNING 2025-08-21 08:42:47,498 basehttp 36788 27160 "POST /api/accounts/register/ HTTP/1.1" 400 272
WARNING 2025-08-21 08:43:32,234 log 36788 37876 Not Found: /
WARNING 2025-08-21 08:43:32,236 basehttp 36788 37876 "GET / HTTP/1.1" 404 3407
WARNING 2025-08-21 08:43:32,810 log 36788 37876 Not Found: /favicon.ico
WARNING 2025-08-21 08:43:32,814 basehttp 36788 37876 "GET /favicon.ico HTTP/1.1" 404 3458
ERROR 2025-08-21 08:50:57,718 log 36788 5716 Internal Server Error: /admin
Traceback (most recent call last):
  File "C:\Users\JOSH\AppData\Roaming\Python\Python313\site-packages\django\core\handlers\exception.py", line 55, in inner
    response = get_response(request)
  File "C:\Users\JOSH\AppData\Roaming\Python\Python313\site-packages\django\utils\deprecation.py", line 136, in __call__
    response = self.process_response(request, response)
  File "C:\Users\JOSH\AppData\Roaming\Python\Python313\site-packages\django\middleware\common.py", line 108, in process_response
    return self.response_redirect_class(self.get_full_path_with_slash(request))
                                        ~~~~~~~~~~~~~~~~~~~~~~~~~~~~~^^^^^^^^^
  File "C:\Users\JOSH\AppData\Roaming\Python\Python313\site-packages\django\middleware\common.py", line 87, in get_full_path_with_slash
    raise RuntimeError(
    ...<9 lines>...
    )
RuntimeError: You called this URL via POST, but the URL doesn't end in a slash and you have APPEND_SLASH set. Django can't redirect to the slash URL while maintaining POST data. Change your form to point to localhost:8000/admin/ (note the trailing slash), or set APPEND_SLASH=False in your Django settings.
ERROR 2025-08-21 08:50:57,722 basehttp 36788 5716 "POST /admin HTTP/1.1" 500 83603
INFO 2025-08-21 08:52:14,451 basehttp 36788 36056 "GET /admin HTTP/1.1" 301 0
INFO 2025-08-21 08:52:14,480 basehttp 36788 14752 "GET /admin/ HTTP/1.1" 302 0
INFO 2025-08-21 08:52:14,622 basehttp 36788 14752 "GET /admin/login/?next=/admin/ HTTP/1.1" 200 4158
INFO 2025-08-21 08:52:14,926 basehttp 36788 14752 "GET /static/admin/css/base.css HTTP/1.1" 200 21544
INFO 2025-08-21 08:52:14,947 basehttp 36788 7900 "GET /static/admin/css/nav_sidebar.css HTTP/1.1" 200 2810
INFO 2025-08-21 08:52:14,952 basehttp 36788 14752 "GET /static/admin/js/nav_sidebar.js HTTP/1.1" 200 3063
INFO 2025-08-21 08:52:14,955 basehttp 36788 26868 "GET /static/admin/css/dark_mode.css HTTP/1.1" 200 2682
INFO 2025-08-21 08:52:14,956 basehttp 36788 34156 "GET /static/admin/css/responsive.css HTTP/1.1" 200 17905
INFO 2025-08-21 08:52:14,960 basehttp 36788 32208 "GET /static/admin/css/login.css HTTP/1.1" 200 958
INFO 2025-08-21 08:52:14,974 basehttp 36788 25048 "GET /static/admin/js/theme.js HTTP/1.1" 200 1943
INFO 2025-08-21 08:52:28,275 basehttp 36788 25048 "POST /admin/login/?next=/admin/ HTTP/1.1" 200 4319
INFO 2025-08-21 08:52:50,496 basehttp 36788 25048 "POST /admin/login/?next=/admin/ HTTP/1.1" 200 4319
INFO 2025-08-21 08:53:06,901 basehttp 36788 25048 "POST /admin/login/?next=/admin/ HTTP/1.1" 200 4319
INFO 2025-08-21 08:53:25,146 basehttp 36788 25048 "GET /admin/ HTTP/1.1" 302 0
INFO 2025-08-21 08:53:25,165 basehttp 36788 25048 "GET /admin/login/?next=/admin/ HTTP/1.1" 200 4158
INFO 2025-08-21 08:53:49,462 basehttp 36788 25048 "POST /admin/login/?next=/admin/ HTTP/1.1" 200 4319
WARNING 2025-08-21 08:57:15,889 log 36788 26676 Not Found: /accounts/register
WARNING 2025-08-21 08:57:15,891 basehttp 36788 26676 "GET /accounts/register HTTP/1.1" 404 3476
WARNING 2025-08-21 08:58:05,642 log 36788 26676 Method Not Allowed: /api/accounts/register/
WARNING 2025-08-21 08:58:05,643 basehttp 36788 26676 "GET /api/accounts/register/ HTTP/1.1" 405 10446
INFO 2025-08-21 08:58:05,748 basehttp 36788 36048 "GET /static/rest_framework/css/prettify.css HTTP/1.1" 200 817
INFO 2025-08-21 08:58:05,748 basehttp 36788 38232 "GET /static/rest_framework/css/bootstrap-tweaks.css HTTP/1.1" 200 3426
INFO 2025-08-21 08:58:05,754 basehttp 36788 26676 "GET /static/rest_framework/css/bootstrap.min.css HTTP/1.1" 200 121457
INFO 2025-08-21 08:58:05,764 basehttp 36788 33200 "GET /static/rest_framework/css/default.css HTTP/1.1" 200 1152
INFO 2025-08-21 08:58:05,791 basehttp 36788 36808 "GET /static/rest_framework/js/ajax-form.js HTTP/1.1" 200 3796
INFO 2025-08-21 08:58:05,791 basehttp 36788 38232 "GET /static/rest_framework/js/csrf.js HTTP/1.1" 200 1793
INFO 2025-08-21 08:58:05,804 basehttp 36788 26676 "GET /static/rest_framework/js/prettify-min.js HTTP/1.1" 200 13632
INFO 2025-08-21 08:58:05,804 basehttp 36788 33200 "GET /static/rest_framework/js/default.js HTTP/1.1" 200 1268
INFO 2025-08-21 08:58:05,812 basehttp 36788 36808 "GET /static/rest_framework/js/load-ajax-form.js HTTP/1.1" 200 59
INFO 2025-08-21 08:58:05,820 basehttp 36788 36048 "GET /static/rest_framework/js/bootstrap.min.js HTTP/1.1" 200 39680
INFO 2025-08-21 08:58:05,840 basehttp 36788 33200 "GET /static/rest_framework/img/grid.png HTTP/1.1" 200 1458
INFO 2025-08-21 08:58:05,841 basehttp 36788 14016 "GET /static/rest_framework/js/jquery-3.7.1.min.js HTTP/1.1" 200 87533
INFO 2025-08-21 09:05:54,971 basehttp 36788 28164 "GET /admin/ HTTP/1.1" 302 0
INFO 2025-08-21 09:05:55,011 basehttp 36788 28164 "GET /admin/login/?next=/admin/ HTTP/1.1" 200 4158
INFO 2025-08-21 09:05:55,156 basehttp 36788 28164 "GET /static/admin/css/base.css HTTP/1.1" 304 0
INFO 2025-08-21 09:05:55,167 basehttp 36788 23136 "GET /static/admin/css/dark_mode.css HTTP/1.1" 304 0
INFO 2025-08-21 09:05:55,168 basehttp 36788 28164 "GET /static/admin/css/login.css HTTP/1.1" 304 0
INFO 2025-08-21 09:05:55,169 basehttp 36788 14084 "GET /static/admin/css/nav_sidebar.css HTTP/1.1" 304 0
INFO 2025-08-21 09:05:55,171 basehttp 36788 18800 "GET /static/admin/css/responsive.css HTTP/1.1" 304 0
INFO 2025-08-21 09:05:55,241 basehttp 36788 18800 "GET /static/admin/js/theme.js HTTP/1.1" 304 0
INFO 2025-08-21 09:05:55,242 basehttp 36788 14084 "GET /static/admin/js/nav_sidebar.js HTTP/1.1" 304 0
INFO 2025-08-21 09:06:51,580 basehttp 36788 14084 "GET /api/accounts/register HTTP/1.1" 301 0
WARNING 2025-08-21 09:06:51,597 log 36788 18800 Method Not Allowed: /api/accounts/register/
WARNING 2025-08-21 09:06:51,598 basehttp 36788 18800 "GET /api/accounts/register/ HTTP/1.1" 405 10446
INFO 2025-08-21 09:06:51,699 basehttp 36788 18800 "GET /static/rest_framework/css/bootstrap.min.css HTTP/1.1" 304 0
INFO 2025-08-21 09:06:51,705 basehttp 36788 14256 "GET /static/rest_framework/js/jquery-3.7.1.min.js HTTP/1.1" 304 0
INFO 2025-08-21 09:06:51,705 basehttp 36788 18800 "GET /static/rest_framework/css/default.css HTTP/1.1" 304 0
INFO 2025-08-21 09:06:51,705 basehttp 36788 28164 "GET /static/rest_framework/css/bootstrap-tweaks.css HTTP/1.1" 304 0
INFO 2025-08-21 09:06:51,705 basehttp 36788 23136 "GET /static/rest_framework/css/prettify.css HTTP/1.1" 304 0
INFO 2025-08-21 09:06:51,712 basehttp 36788 27072 "GET /static/rest_framework/js/ajax-form.js HTTP/1.1" 304 0
INFO 2025-08-21 09:06:51,713 basehttp 36788 18800 "GET /static/rest_framework/js/default.js HTTP/1.1" 304 0
INFO 2025-08-21 09:06:51,713 basehttp 36788 28164 "GET /static/rest_framework/js/bootstrap.min.js HTTP/1.1" 304 0
INFO 2025-08-21 09:06:51,713 basehttp 36788 14256 "GET /static/rest_framework/js/prettify-min.js HTTP/1.1" 304 0
INFO 2025-08-21 09:06:51,714 basehttp 36788 18628 "GET /static/rest_framework/js/csrf.js HTTP/1.1" 304 0
INFO 2025-08-21 09:06:51,714 basehttp 36788 23136 "GET /static/rest_framework/js/load-ajax-form.js HTTP/1.1" 304 0
INFO 2025-08-21 09:06:51,745 basehttp 36788 23136 "GET /static/rest_framework/img/grid.png HTTP/1.1" 304 0
